<mujoco model="planer_2r">
    <compiler angle="radian" meshdir="assets" autolimits="true"/>
    <option integrator="implicitfast"/>

    <default>
        <default class="link">
            <geom type="capsule" size="0.05 0.25" rgba="0.8 0.6 0.4 1"/>
            </default>
    </default>

    <worldbody>
        <body name="base" pos="0 0 0">
            <geom type="box" size="0.05 0.05 0.05" rgba="1 0 0 1"/>

            <body name="link1" pos="0 0 0">
                <joint name="joint1" type="hinge" axis="0 0 1" range="-3.14 3.14"/>
                <geom type="box" size="0.025 0.025 0.25" pos="0.25 0 0" euler="0 1.57 0" rgba="0.8 0.6 0.4 1"/>

                <body name="joint_link12" pos="0.5 0 0">
                    <geom type="box" size="0.05 0.05 0.05" rgba="0 1 0 1"/>

                    <body name="link2" pos="0 0 0" euler="0 0 0">
                        <joint name="joint2" type="hinge" axis="0 0 1" range="-3.14 3.14"/>
                        <geom type="box" size="0.025 0.025 0.25" pos="0.25 0 0" euler="0 1.57 0" rgba="0.5 0.6 0.4 1"/>
        
                    </body>
                </body>
            </body>
        </body>
    </worldbody>

    <actuator>
        <general name="pos_actuator1" joint="joint1" ctrlrange="-3.14 3.14" ctrllimited="true"/>
        <general name="pos_actuator2" joint="joint2" ctrlrange="-3.14 3.14" ctrllimited="true"/>
    </actuator>

    <keyframe>
        <key name="home" qpos="0 1" ctrl="0 1"/>
    </keyframe>
</mujoco>