<?xml version="1.0" ?>
<mujoco model="two_r_robot">
    <compiler angle="radian" />
    <default>
        <joint limited="true" damping="1"/>
        <geom type="cylinder" size="0.05 0.5" rgba="0.8 0.6 0.4 1" />
    </default>
    <worldbody>
        <body name="base" pos="0 0 0">
            <geom name="base" type="box" size="0.05 0.05 0.05" rgba="0 0 1 1"/>
            <body name="link1" pos="0 0 0.05">
                <joint name="joint1" type="hinge" pos="0 0 0" axis="0 1 0" range="-1.57 1.57"/>
                <geom fromto="0 0 0 0 0 1" size="0.05" rgba="0 1 0 1"/>
                <body name="link2" pos="0 0 1">
                    <joint name="joint2" type="hinge" pos="0 0 0" axis="0 1 0" range="-1.57 1.57"/>
                    <geom fromto="0 0 0 0 0 1" size="0.05" rgba="1 0 0 1"/>
                </body>
            </body>
        </body>
    </worldbody>
    <actuator>
        <motor joint="joint1" ctrlrange="-1 1" ctrllimited="true"/>
        <motor joint="joint2" ctrlrange="-1 1" ctrllimited="true"/>
    </actuator>
</mujoco>
